I'm sorry, but an uncaught exception occurred.

While running game code:
  File "game/script.rpy", line 162, in script call
    call run_scenes
  File "game/script.rpy", line 137, in script
    $ response, scene_completed = game.message_npc_and_get_response(user_input)
  File "game/script.rpy", line 137, in <module>
    $ response, scene_completed = game.message_npc_and_get_response(user_input)
  File "game/script.rpy", line 52, in message_npc_and_get_response
    scene_id=self.scene_id,
AttributeError: 'Game' object has no attribute 'scene_id'

-- Full Traceback ------------------------------------------------------------

Full traceback:
  File "game/script.rpy", line 162, in script call
    call run_scenes
  File "game/script.rpy", line 137, in script
    $ response, scene_completed = game.message_npc_and_get_response(user_input)
  File "/home/carl/Pretence/renpy-8.1.1-sdk/renpy/ast.py", line 1138, in execute
    renpy.python.py_exec_bytecode(self.code.bytecode, self.hide, store=self.store)
  File "/home/carl/Pretence/renpy-8.1.1-sdk/renpy/python.py", line 1122, in py_exec_bytecode
    exec(bytecode, globals, locals)
  File "game/script.rpy", line 137, in <module>
    $ response, scene_completed = game.message_npc_and_get_response(user_input)
  File "game/script.rpy", line 52, in message_npc_and_get_response
    scene_id=self.scene_id,
AttributeError: 'Game' object has no attribute 'scene_id'

Linux-6.2.0-26-generic-x86_64-with-glibc2.35 x86_64
Ren'Py 8.1.1.23060707
CallumTest 1.0
Mon Aug 28 17:11:59 2023
