I'm sorry, but an uncaught exception occurred.

While running game code:
  File "game/script.rpy", line 167, in script call
    call run_scenes
  File "game/script.rpy", line 117, in script
    show scene_image
Exception: DynamicImage '[scene_image_default]': could not find image. ('TraumaGame/callum.png')

-- Full Traceback ------------------------------------------------------------

Full traceback:
  File "game/script.rpy", line 167, in script call
    call run_scenes
  File "game/script.rpy", line 117, in script
    show scene_image
  File "/home/carl/pretence/renpy-8.1.1-sdk/renpy/ast.py", line 1428, in execute
    show_imspec(self.imspec, atl=getattr(self, "atl", None))
  File "/home/carl/pretence/renpy-8.1.1-sdk/renpy/ast.py", line 1391, in show_imspec
    renpy.config.show(name,
  File "/home/carl/pretence/renpy-8.1.1-sdk/renpy/exports.py", line 759, in show
    sls.add(layer, img, key, zorder, behind, at_list=at_list, name=name, atl=atl, default_transform=default_transform, transient=transient)
  File "/home/carl/pretence/renpy-8.1.1-sdk/renpy/display/core.py", line 1266, in add
    thing.set_transform_event("show")
  File "/home/carl/pretence/renpy-8.1.1-sdk/renpy/display/transform.py", line 695, in set_transform_event
    self.child.set_transform_event(event)
  File "/home/carl/pretence/renpy-8.1.1-sdk/renpy/display/image.py", line 501, in set_transform_event
    return self.target.set_transform_event(event)
  File "/home/carl/pretence/renpy-8.1.1-sdk/renpy/display/image.py", line 760, in set_transform_event
    self.find_target()
  File "/home/carl/pretence/renpy-8.1.1-sdk/renpy/display/image.py", line 683, in find_target
    raise Exception(error)
Exception: DynamicImage '[scene_image_default]': could not find image. ('TraumaGame/callum.png')

Linux-5.19.0-46-generic-x86_64-with-glibc2.35 x86_64
Ren'Py 8.1.1.23060707
CallumTest 1.0
Wed Jul 26 13:39:07 2023
